<?xml version="1.0"?>
<!-- Revolute-Revolute Manipulator -->
<robot name="sj605" xmlns:xacro="http://www.ros.org/wiki/xacro">

  <!-- Constants for robot dimensions -->
  <xacro:property name="pi" value="3.1415926535897931"/>
  <xacro:property name="deg" value="0.017453293"/>
  <!-- Import all Gazebo-customization elements, including Gazebo colors -->
  <xacro:include filename="$(find sj605_description)/urdf/sj605.gazebo" />
  <!-- Import Rviz colors -->
  <xacro:include filename="$(find sj605_description)/urdf/materials.xacro" />

  <!-- Used for fixing robot to Gazebo 'base_link' -->
  <link name="world"/>
  <joint name="fixed" type="fixed">
    <parent link="world"/>
    <child link="link1"/>
  </joint>
  <!-- Base Link -->
  <link name="link1">
    <collision>
      <origin xyz="0 0 0.1" rpy="0 0 0"/>
      <geometry>
	<cylinder radius="0.2" length="0.1"/>
      </geometry>
    </collision>
    <visual>
      <origin xyz="0 0 0" rpy="0 0 0"/>
      <geometry>
	<mesh filename="package://sj605_description/meshes/link_1.dae"/>
      </geometry>
      <material name="orange"/>
    </visual>
    <inertial>
      <origin xyz="0 0 0" rpy="0 0 0"/>
      <mass value="5"/>
      <inertia ixx="0.06" ixy="0" ixz="0" iyy="0.07" iyz="0" izz="0.01"/>
    </inertial>
  </link>
  <!-- 2nd Link -->
  <link name="link2">
    <collision>
      <origin xyz="0 0 -0.73" rpy="0 0 0"/>
      <geometry>
	<mesh filename="package://sj605_description/meshes/link_2.dae"/>
      </geometry>
    </collision>
    <visual>
      <origin xyz="0 0 -0.73" rpy="0 0 0"/>
      <geometry>
	<mesh filename="package://sj605_description/meshes/link_2.dae"/>
      </geometry>
      <material name="black"/>
    </visual>
    <inertial>
      <origin xyz="0 0 0" rpy="0 0 0"/>
      <mass value="2"/>
      <inertia
	  ixx="0.11" ixy="0.0" ixz="0.0" iyy="0.11" iyz="0.0" izz="0.094"/>
    </inertial>
  </link>
  <!-- 3rd Link -->
  <link name="link3">
    <collision>
      <origin xyz="0 0.0425 1.91" rpy="0 1.57 0"/>
      <geometry>
	<mesh filename="package://sj605_description/meshes/3.stl"/>
      </geometry>
    </collision>
    <visual>
      <origin xyz="0 0.0425 1.91" rpy="0 0 0"/>
      <geometry>
	<mesh filename="package://sj605_description/meshes/link_3.dae"/>
      </geometry>
      <material name="black"/>
    </visual>
    <inertial>
      <origin xyz="0 0.0425 1.91" rpy="0 0 0"/>
      <mass value="1"/>
      <inertia
	  ixx="1.65" ixy="0" ixz="0" iyy="1.65" iyz="0" izz="0.093"/>
    </inertial>
  </link>
  <!-- 4th Link -->
  <link name="link4">
    <collision>
      <origin xyz="0.275 0.04 0" rpy="0 0 0"/>
      <geometry>
	<mesh filename="package://sj605_description/meshes/4.stl"/>
      </geometry>
    </collision>
    <visual>
      <origin xyz="0.275 0.04 0" rpy="0 0 0"/>
      <geometry>
	<mesh filename="package://sj605_description/meshes/link_4.dae"/>
      </geometry>
      <material name="orange"/>
    </visual>
    <inertial>
      <origin xyz="0.275 0 0" rpy="0 0 0"/>
      <mass value="0.6"/>
      <inertia
	  ixx="0.041" ixy="0" ixz="0.0" iyy="0.097" iyz="0.0" izz="0.097"/>
    </inertial>
  </link>
  <!-- 5th Link -->
  <link name="link5">
    <collision>
      <origin xyz="1.04 0.11 0" rpy="0 0 0"/>
      <geometry>
	<mesh filename="package://sj605_description/meshes/5.stl"/>
      </geometry>
    </collision>
    <visual>
      <origin xyz="1.04 0.11 0" rpy="0 0 0"/>
      <geometry>
	<mesh filename="package://sj605_description/meshes/link_5.dae"/>
      </geometry>
      <material name="black"/>
    </visual>
    <inertial>
      <origin xyz="0.51 0 0" rpy="0 0 0"/>
      <mass value="0.2"/>
      <inertia
	  ixx="0.0039" ixy="0.0" ixz="0.0" iyy="0.0060" iyz="0.0" izz="0.0060"/>
    </inertial>
  </link>
  <!-- 6th Link -->
  <link name="link6">
    <collision>
      <origin xyz="0.51 -0.07 0" rpy="0 0 0"/>
      <geometry>
	<mesh filename="package://sj605_description/meshes/6.stl"/>
      </geometry>
    </collision>
    <visual>
      <origin xyz="0.51 -0.07 0" rpy="0 0 0"/>
      <geometry>
	<mesh filename="package://sj605_description/meshes/link_6.dae"/>
      </geometry>
      <material name="orange"/>
    </visual>
    <inertial>
      <origin xyz="0.51 0 0" rpy="0 0 0"/>
      <mass value="0.1"/>
      <inertia
	  ixx="0.0039" ixy="0.0" ixz="0.0" iyy="0.0060" iyz="0.0" izz="0.0060"/>
    </inertial>
  </link>
  <!-- Top Link -->
  <link name="link7">
    <collision>
      <origin xyz="0.05 0 0" rpy="0 0 0"/>
      <geometry>
	<box size="0.2 0.2 0.2"/>
      </geometry>
    </collision>

    <visual>
      <origin xyz="0.05 0 0" rpy="0 ${-pi/2} 0"/>
      <geometry>
	<box size="0.2 0.2 0.2"/>
      </geometry>
      <material name="black"/>
    </visual>

    <inertial>
      <origin xyz="0.05 0 0" rpy="0 0 0"/>
      <mass value="0.05"/>
      <inertia
	  ixx="0.002" ixy="0.0" ixz="0.0"
	  iyy="0.0015" iyz="0.0"
	  izz="0.0015"/>
    </inertial>
  </link>
  <!-- Joint -->
  <joint name="joint1" type="revolute">
    <parent link="link1"/>
    <child link="link2"/>
    <origin xyz="0 0 0.73" rpy="0 0 0"/>
    <limit lower="-3.14" upper="3.14" effort="1000" velocity="${45*deg}"/>
    <axis xyz="0 0 1"/>
    <dynamics damping="0.7"/>
  </joint>
  <joint name="joint2" type="revolute">
    <parent link="link2"/>
    <child link="link3"/>
    <origin xyz="0 1.081 0" rpy="0 0 0"/>
    <limit lower="${-45*deg}" upper="${90*deg}" effort="500" velocity="${20*deg}"/>
    <axis xyz="0 -1 0"/>
    <dynamics damping="0.7"/>
  </joint>
  <joint name="joint3" type="revolute">
    <parent link="link3"/>
    <child link="link4"/>
    <origin xyz="0 -1.00 3.8" rpy="0 0 0"/>
    <limit lower="${-90*deg}" upper="${180*deg}" effort="500" velocity="${20*deg}"/>
    <axis xyz="0 -1 0"/>
    <dynamics damping="0.7"/>
  </joint>
  <joint name="joint4" type="revolute">
    <parent link="link4"/>
    <child link="link5"/>
    <origin xyz="1.28 0 0" rpy="0 0 0"/>
    <limit lower="-3.14" upper="3.14" effort="100" velocity="${10*deg}"/>
    <axis xyz="1 0 0"/>
    <dynamics damping="0.7"/>
  </joint>
  <joint name="joint5" type="revolute">
    <parent link="link5"/>
    <child link="link6"/>
    <origin xyz="1.46 0 0" rpy="0 0 0"/>
    <limit lower="${-90*deg}" upper="${90*deg}" effort="100" velocity="${20*deg}"/>
    <axis xyz="0 -1 0"/>
    <dynamics damping="0.7"/>
  </joint>
  <joint name="joint6" type="revolute">
    <parent link="link6"/>
    <child link="link7"/>
    <limit lower="${-100*deg}" upper="${100*deg}" effort="100" velocity="${20*deg}"/>
    <origin xyz="1.2 0 0" rpy="0 0 0"/>
    <axis xyz="1 0 0"/>
    <dynamics damping="0.7"/>
  </joint>


  <transmission name="tranb">
    <type>transmission_interface/SimpleTransmission</type>
    <joint name="joint1">
      <hardwareInterface>hardware_interface/EffortJointInterface</hardwareInterface>
    </joint>
    <actuator name="motor1">
      <hardwareInterface>hardware_interface/EffortJointInterface</hardwareInterface>
      <mechanicalReduction>1</mechanicalReduction>
    </actuator>
  </transmission>
  <transmission name="tran2">
    <type>transmission_interface/SimpleTransmission</type>
    <joint name="joint2">
      <hardwareInterface>hardware_interface/EffortJointInterface</hardwareInterface>
    </joint>
    <actuator name="motor2">
      <hardwareInterface>hardware_interface/EffortJointInterface</hardwareInterface>
      <mechanicalReduction>1</mechanicalReduction>
    </actuator>
  </transmission>
  <transmission name="tran3">
    <type>transmission_interface/SimpleTransmission</type>
    <joint name="joint3">
      <hardwareInterface>hardware_interface/EffortJointInterface</hardwareInterface>
    </joint>
    <actuator name="motor3">
      <hardwareInterface>hardware_interface/EffortJointInterface</hardwareInterface>
      <mechanicalReduction>1</mechanicalReduction>
    </actuator>
  </transmission>
  <transmission name="tran4">
    <type>transmission_interface/SimpleTransmission</type>
    <joint name="joint4">
      <hardwareInterface>hardware_interface/EffortJointInterface</hardwareInterface>
    </joint>
    <actuator name="motor4">
      <hardwareInterface>hardware_interface/EffortJointInterface</hardwareInterface>
      <mechanicalReduction>1</mechanicalReduction>
    </actuator>
  </transmission>
  <transmission name="tran5">
    <type>transmission_interface/SimpleTransmission</type>
    <joint name="joint5">
      <hardwareInterface>hardware_interface/EffortJointInterface</hardwareInterface>
    </joint>
    <actuator name="motor5">
      <hardwareInterface>hardware_interface/EffortJointInterface</hardwareInterface>
      <mechanicalReduction>1</mechanicalReduction>
    </actuator>
  </transmission>
  <transmission name="tran6">
    <type>transmission_interface/SimpleTransmission</type>
    <joint name="joint6">
      <hardwareInterface>hardware_interface/EffortJointInterface</hardwareInterface>
    </joint>
    <actuator name="motor6">
      <hardwareInterface>hardware_interface/EffortJointInterface</hardwareInterface>
      <mechanicalReduction>1</mechanicalReduction>
    </actuator>
  </transmission>
</robot>
